<?xml version="1.0"?>
<robot name="3dof">

  <link name="world"/>
  <link name="base_link">
    <visual>
      <origin xyz="0 0 0.01"/>
      <geometry>
        <box size="0.1 0.1 0.02"/>  
      </geometry>
    </visual>
    <inertial>
      <mass value="0.1"/>
      <inertia ixx="8.6e-05" ixy="0.0" ixz="0.0" iyy="8.6e-05" iyz="0.0" izz="1.6e-04"/>
    </inertial>
  </link>

  <link name="link_1">
    <visual>
      <origin xyz="0.0 0.0 0.005"/>
      <geometry>
        <cylinder radius="0.03" length="0.01"/>
      </geometry>  
    </visual>
    <inertial>
      <mass value="0.06"/>
      <inertia ixx="1.4e-05" ixy="0.0" ixz="0.0" iyy="1.4e-05" iyz="0.0" izz="2.7e-05"/>
    </inertial>
  </link>

  <link name="link_2">
    <visual>
      <origin xyz="0.0 0.0 0.065"/>
      <geometry>
        <box size="0.03 0.03 0.13"/>
      </geometry>
    </visual>
    <inertial>
      <mass value="0.05"/>
      <inertia ixx="7.41e-05" ixy="0.0" ixz="0.0" iyy="7.41e-05" iyz="0.0" izz="7.5e-06"/>
    </inertial>
  </link>

  <link name="link_3">
    <visual>
      <origin xyz="0.0 0.0 0.05"/>
      <geometry>
        <box size="0.03 0.03 0.10"/>
      </geometry>
    </visual>
    <inertial>
      <mass value="0.04"/>
      <inertia ixx="3.6e-05" ixy="0.0" ixz="0.0" iyy="3.6e-05" iyz="0.0" izz="6e-06"/>
    </inertial>
  </link>

  <joint name="world_to_base" type="fixed">
  <parent link="world"/>
  <child link="base_link"/>
  
  </joint>
  <joint name="base_to_link_1" type="revolute">
    <origin xyz="0.0 0.0 0.02"/>
    <parent link="base_link"/>
    <child link="link_1"/>
    <limit lower="-3.14" upper="3.14" effort="100" velocity="100"/>
    <axis xyz="0.0 0.0 1"/>
  </joint>

  <joint name="link_1_to_link_2" type="revolute">
    <origin xyz="0.0 0.0 0.01"/>
    <parent link="link_1"/>
    <child link="link_2"/>
    <limit lower="-1.57" upper="1.57" effort="100" velocity="100"/>
    <axis xyz="1 0.0 0.0"/>
  </joint>

  <joint name="link_2_to_link_3" type="revolute">
    <origin xyz="0.0 0.0 0.13"/>
    <parent link="link_2"/>
    <child link="link_3"/>
    <limit lower="-1.57" upper="1.57" effort="100" velocity="100"/>
    <axis xyz="1 0.0 0.0"/>
  </joint>

  <transmission name="trans1">
    <type>transmission_interface/SimpleTransmission</type>
    <joint name="base_to_link_1">
        <hardwareInterface>hardware_interface/EffortJointInterface</hardwareInterface>
    </joint>
    <actuator name="motor1">
        <hardwareInterface>hardware_interface/EffortJointInterface</hardwareInterface>
        <mechanicalReduction>1</mechanicalReduction>
    </actuator>
  </transmission>

  <transmission name="trans2">
    <type>transmission_interface/SimpleTransmission</type>
    <joint name="link_1_to_link_2">
        <hardwareInterface>hardware_interface/EffortJointInterface</hardwareInterface>
    </joint>
    <actuator name="motor2">
        <hardwareInterface>hardware_interface/EffortJointInterface</hardwareInterface>
        <mechanicalReduction>1</mechanicalReduction>
    </actuator>
  </transmission>

  <transmission name="trans3">
    <type>transmission_interface/SimpleTransmission</type>
    <joint name="link_2_to_link_3">
        <hardwareInterface>hardware_interface/EffortJointInterface</hardwareInterface>
    </joint>
    <actuator name="motor3">
        <hardwareInterface>hardware_interface/EffortJointInterface</hardwareInterface>
        <mechanicalReduction>1</mechanicalReduction>
    </actuator>
  </transmission>

  <gazebo>
      <plugin name="gazebo_ros_control" filename="libgazebo_ros_control.so">
          <robotNamespace>/3dof</robotNamespace>
      </plugin>
  </gazebo>

  <gazebo reference="base_link">
        <mu1>0.01</mu1>
        <mu2>0.01</mu2>
        <material>Gazebo/Gray</material>
        <!-- <selfCollide>true</selfCollide> -->
        <gravity>true</gravity>
        <minDepth>0.01</minDepth>
    </gazebo>

    <gazebo reference="link_1">
        <mu1>0.01</mu1>
        <mu2>0.01</mu2>
        <material>Gazebo/White</material>
        <!-- <selfCollide>true</selfCollide> -->
        <gravity>true</gravity>
        <minDepth>0.01</minDepth>
    </gazebo>

    <gazebo reference="link_2">
        <mu1>0.01</mu1>
        <mu2>0.01</mu2>
        <material>Gazebo/Gray</material>
        <!-- <selfCollide>true</selfCollide> -->
        <gravity>true</gravity>
        <minDepth>0.01</minDepth>
    </gazebo>

    <gazebo reference="link_3">
        <mu1>0.01</mu1>
        <mu2>0.01</mu2>
        <material>Gazebo/White</material>
        <!-- <selfCollide>true</selfCollide> -->
        <gravity>true</gravity>
        <minDepth>0.01</minDepth>
    </gazebo>

</robot>